Workbook

Sheet WK 47
A1: CIM | B1: Agent Name | C1: Position | D1: Stage | E1: FT/PT | F1: Wave | G1: 45607 | I1: 45608 | K1: 45609 | M1: 45610 | O1: 45611 | Q1: 45612 | S1: 45613
G2: Monday | I2: Tuesday | K2: Wednesday | M2: Thursday | O2: Friday | Q2: Saturday | S2: Sunday
G3: From | H3: To | I3: From | J3: To | K3: From | L3: To | M3: From | N3: To | O3: From | P3: To | Q3: From | R3: To | S3: From | T3: To | U3: Working Hrs | V3: Preference was | W3: Difference | X3: Pattern
A4: 10316549 | B4: Ahmed Mamdouh | C4: CSR | D4: Production | E4: FT | F4: 1 | G4: 0.45833333 | H4: 0.875 | I4: 0.45833333 | J4: 0.875 | K4: 0.45833333 | L4: 0.875 | M4: 0.45833333 | N4: 0.875 | O4: OFF | P4: OFF | Q4: OFF | R4: OFF | S4: 0.45833333 | T4: 0.66666667 | U4: 45 | V4: 45 | W4: -1.4210855e-14 | X4: 0.41666667 | Y4: =IF(G4="Off","",IF(AND(G4>=TIME(9,0,0),G4<=TIME(10,0,0)),"early",IF(OR(G4=TIME(11,0,0),G4=TIME(12,0,0)),"late",""))) -> late | Z4: =IF(H4="Off","",IF(AND(H4>=TIME(9,0,0),H4<=TIME(10,0,0)),"early",IF(OR(H4=TIME(11,0,0),H4=TIME(12,0,0)),"late",""))) | AA4: =IF(I4="Off","",IF(AND(I4>=TIME(9,0,0),I4<=TIME(10,0,0)),"early",IF(OR(I4=TIME(11,0,0),I4=TIME(12,0,0)),"late",""))) -> late
A5: 10317147 | B5: Asalla Metwally | C5: CSR | D5: Production | E5: FT | F5: 1 | G5: OFF | H5: OFF | I5: 0.375 | J5: 0.79166667 | K5: 0.375 | L5: 0.79166667 | M5: 0.375 | N5: 0.79166667 | O5: 0.375 | P5: 0.79166667 | Q5: 0.45833333 | R5: 0.66666667 | S5: OFF | T5: OFF | U5: 45 | V5: 45 | W5: -7.1054274e-15 | X5: 0.41666667 | Y5: =IF(G5="Off","",IF(AND(G5>=TIME(9,0,0),G5<=TIME(10,0,0)),"early",IF(OR(G5=TIME(11,0,0),G5=TIME(12,0,0)),"late",""))) | AA5: =IF(I5="Off","",IF(AND(I5>=TIME(9,0,0),I5<=TIME(10,0,0)),"early",IF(OR(I5=TIME(11,0,0),I5=TIME(12,0,0)),"late",""))) -> early
A6: 10250963 | B6: Dina Hanafy | C6: CSR | D6: Production | E6: FT | F6: 1 | G6: OFF | H6: OFF | I6: 0.45833333 | J6: 0.875 | K6: 0.45833333 | L6: 0.875 | M6: 0.45833333 | N6: 0.875 | O6: 0.45833333 | P6: 0.875 | Q6: 0.45833333 | R6: 0.66666667 | S6: OFF | T6: OFF | U6: 45 | V6: 45 | W6: -1.4210855e-14 | X6: 0.41666667 | Y6: =IF(G6="Off","",IF(AND(G6>=TIME(9,0,0),G6<=TIME(10,0,0)),"early",IF(OR(G6=TIME(11,0,0),G6=TIME(12,0,0)),"late",""))) | AA6: =IF(I6="Off","",IF(AND(I6>=TIME(9,0,0),I6<=TIME(10,0,0)),"early",IF(OR(I6=TIME(11,0,0),I6=TIME(12,0,0)),"late",""))) -> late
A7: 10316530 | B7: Hassan Hussain | C7: CSR | D7: Production | E7: FT | F7: 1 | G7: OFF | H7: OFF | I7: 0.45833333 | J7: 0.875 | K7: 0.45833333 | L7: 0.875 | M7: 0.45833333 | N7: 0.875 | O7: 0.45833333 | P7: 0.875 | Q7: 0.45833333 | R7: 0.66666667 | S7: OFF | T7: OFF | U7: 45 | V7: 45 | W7: -1.4210855e-14 | X7: 0.41666667 | Y7: =IF(G7="Off","",IF(AND(G7>=TIME(9,0,0),G7<=TIME(10,0,0)),"early",IF(OR(G7=TIME(11,0,0),G7=TIME(12,0,0)),"late",""))) | AA7: =IF(I7="Off","",IF(AND(I7>=TIME(9,0,0),I7<=TIME(10,0,0)),"early",IF(OR(I7=TIME(11,0,0),I7=TIME(12,0,0)),"late",""))) -> late
A8: 10317943 | B8: Hla Badr | C8: CSR | D8: Production | E8: FT | F8: 2 | G8: 0.375 | H8: 0.79166667 | I8: 0.375 | J8: 0.79166667 | K8: 0.375 | L8: 0.79166667 | M8: 0.375 | N8: 0.79166667 | O8: OFF | P8: OFF | Q8: OFF | R8: OFF | S8: 0.45833333 | T8: 0.66666667 | U8: 45 | V8: 45 | W8: 7.1054274e-15 | X8: 0.41666667 | Y8: =IF(G8="Off","",IF(AND(G8>=TIME(9,0,0),G8<=TIME(10,0,0)),"early",IF(OR(G8=TIME(11,0,0),G8=TIME(12,0,0)),"late",""))) -> early | AA8: =IF(I8="Off","",IF(AND(I8>=TIME(9,0,0),I8<=TIME(10,0,0)),"early",IF(OR(I8=TIME(11,0,0),I8=TIME(12,0,0)),"late",""))) -> early
A9: 10317521 | B9: Mariam Gadalkarim | C9: CSR | D9: Production | E9: FT | F9: 2 | G9: 0.375 | H9: 0.79166667 | I9: 0.375 | J9: 0.79166667 | K9: 0.375 | L9: 0.79166667 | M9: 0.375 | N9: 0.79166667 | O9: OFF | P9: OFF | Q9: OFF | R9: OFF | S9: 0.45833333 | T9: 0.66666667 | U9: 45 | V9: 45 | W9: 7.1054274e-15 | X9: 0.41666667 | Y9: =IF(G9="Off","",IF(AND(G9>=TIME(9,0,0),G9<=TIME(10,0,0)),"early",IF(OR(G9=TIME(11,0,0),G9=TIME(12,0,0)),"late",""))) -> early | AA9: =IF(I9="Off","",IF(AND(I9>=TIME(9,0,0),I9<=TIME(10,0,0)),"early",IF(OR(I9=TIME(11,0,0),I9=TIME(12,0,0)),"late",""))) -> early
A10: 10317517 | B10: Mariam Hanna | C10: CSR | D10: Production | E10: FT | F10: 2 | G10: OFF | H10: OFF | I10: 0.375 | J10: 0.79166667 | K10: 0.375 | L10: 0.79166667 | M10: 0.375 | N10: 0.79166667 | O10: 0.375 | P10: 0.79166667 | Q10: 0.45833333 | R10: 0.66666667 | S10: OFF | T10: OFF | U10: 45 | V10: 45 | W10: 7.1054274e-15 | X10: 0.41666667 | Y10: =IF(G10="Off","",IF(AND(G10>=TIME(9,0,0),G10<=TIME(10,0,0)),"early",IF(OR(G10=TIME(11,0,0),G10=TIME(12,0,0)),"late",""))) | AA10: =IF(I10="Off","",IF(AND(I10>=TIME(9,0,0),I10<=TIME(10,0,0)),"early",IF(OR(I10=TIME(11,0,0),I10=TIME(12,0,0)),"late",""))) -> early
A11: 10316540 | B11: Wafaa Elnaby | C11: CSR | D11: Production | E11: FT | F11: 1 | G11: OFF | H11: OFF | I11: 0.45833333 | J11: 0.875 | K11: 0.45833333 | L11: 0.875 | M11: 0.45833333 | N11: 0.875 | O11: 0.45833333 | P11: 0.875 | Q11: 0.45833333 | R11: 0.66666667 | S11: OFF | T11: OFF | U11: 45 | V11: 45 | W11: -1.4210855e-14 | X11: 0.41666667 | Y11: =IF(G11="Off","",IF(AND(G11>=TIME(9,0,0),G11<=TIME(10,0,0)),"early",IF(OR(G11=TIME(11,0,0),G11=TIME(12,0,0)),"late",""))) | AA11: =IF(I11="Off","",IF(AND(I11>=TIME(9,0,0),I11<=TIME(10,0,0)),"early",IF(OR(I11=TIME(11,0,0),I11=TIME(12,0,0)),"late",""))) -> late
A12: 10317522 | B12: Ahmed Hisham | C12: CSR | D12: Production | E12: FT | F12: 2 | G12: 0.45833333 | H12: 0.875 | I12: 0.45833333 | J12: 0.875 | K12: 0.45833333 | L12: 0.875 | M12: 0.45833333 | N12: 0.875 | O12: OFF | P12: OFF | Q12: OFF | R12: OFF | S12: 0.45833333 | T12: 0.66666667 | U12: 45 | V12: 45 | W12: -1.4210855e-14 | X12: 0.41666667 | Y12: =IF(G12="Off","",IF(AND(G12>=TIME(9,0,0),G12<=TIME(10,0,0)),"early",IF(OR(G12=TIME(11,0,0),G12=TIME(12,0,0)),"late",""))) -> late | AA12: =IF(I12="Off","",IF(AND(I12>=TIME(9,0,0),I12<=TIME(10,0,0)),"early",IF(OR(I12=TIME(11,0,0),I12=TIME(12,0,0)),"late",""))) -> late
A13: 10272259 | B13: Aya Hassan | C13: CSR | D13: Production | E13: FT | F13: 2 | G13: 0.5 | H13: 0.875 | I13: OFF | J13: OFF | K13: OFF | L13: OFF | M13: 0.5 | N13: 0.875 | O13: 0.5 | P13: 0.875 | Q13: 0.45833333 | R13: 0.66666667 | S13: 0.45833333 | T13: 0.66666667 | U13: 37 | V13: 37 | W13: 0 | X13: 0.375 | Y13: =IF(G13="Off","",IF(AND(G13>=TIME(9,0,0),G13<=TIME(10,0,0)),"early",IF(OR(G13=TIME(11,0,0),G13=TIME(12,0,0)),"late",""))) -> late | AA13: =IF(I13="Off","",IF(AND(I13>=TIME(9,0,0),I13<=TIME(10,0,0)),"early",IF(OR(I13=TIME(11,0,0),I13=TIME(12,0,0)),"late","")))
A14: 10316618 | B14: Caren Lawendi | C14: CSR | D14: Production | E14: FT | F14: 1 | G14: 0.45833333 | H14: 0.875 | I14: 0.45833333 | J14: 0.875 | K14: 0.45833333 | L14: 0.875 | M14: 0.45833333 | N14: 0.875 | O14: OFF | P14: OFF | Q14: OFF | R14: OFF | S14: 0.45833333 | T14: 0.66666667 | U14: 45 | V14: 45 | W14: -1.4210855e-14 | X14: 0.41666667 | Y14: =IF(G14="Off","",IF(AND(G14>=TIME(9,0,0),G14<=TIME(10,0,0)),"early",IF(OR(G14=TIME(11,0,0),G14=TIME(12,0,0)),"late",""))) -> late | AA14: =IF(I14="Off","",IF(AND(I14>=TIME(9,0,0),I14<=TIME(10,0,0)),"early",IF(OR(I14=TIME(11,0,0),I14=TIME(12,0,0)),"late",""))) -> late
A15: 10295555 | B15: Duaa Elshareeff | C15: CSR | D15: Production | E15: PT | F15: 2 | G15: 0.66666667 | H15: 0.875 | I15: 0.66666667 | J15: 0.875 | K15: 0.66666667 | L15: 0.875 | M15: OFF | N15: OFF | O15: OFF | P15: OFF | Q15: AN | R15: AN | S15: AN | T15: AN | U15: 15 | V15: 25 | W15: 10 | X15: 0.20833333 | Y15: =IF(G15="Off","",IF(AND(G15>=TIME(9,0,0),G15<=TIME(10,0,0)),"early",IF(OR(G15=TIME(11,0,0),G15=TIME(12,0,0)),"late",""))) | AA15: =IF(I15="Off","",IF(AND(I15>=TIME(9,0,0),I15<=TIME(10,0,0)),"early",IF(OR(I15=TIME(11,0,0),I15=TIME(12,0,0)),"late","")))
A16: 10317520 | B16: Farida Gadalkarim | C16: CSR | D16: Production | E16: FT | F16: 2 | G16: 0.375 | H16: 0.79166667 | I16: 0.375 | J16: 0.79166667 | K16: 0.375 | L16: 0.79166667 | M16: 0.375 | N16: 0.79166667 | O16: OFF | P16: OFF | Q16: OFF | R16: OFF | S16: 0.45833333 | T16: 0.66666667 | U16: 45 | V16: 45 | W16: 7.1054274e-15 | X16: 0.41666667 | Y16: =IF(G16="Off","",IF(AND(G16>=TIME(9,0,0),G16<=TIME(10,0,0)),"early",IF(OR(G16=TIME(11,0,0),G16=TIME(12,0,0)),"late",""))) -> early | AA16: =IF(I16="Off","",IF(AND(I16>=TIME(9,0,0),I16<=TIME(10,0,0)),"early",IF(OR(I16=TIME(11,0,0),I16=TIME(12,0,0)),"late",""))) -> early
A17: 10316681 | B17: Habiba Morsy | C17: CSR | D17: Production | E17: FT | F17: 1 | G17: 0.375 | H17: 0.79166667 | I17: 0.375 | J17: 0.79166667 | K17: 0.375 | L17: 0.79166667 | M17: 0.375 | N17: 0.79166667 | O17: OFF | P17: OFF | Q17: OFF | R17: OFF | S17: 0.45833333 | T17: 0.66666667 | U17: 45 | V17: 45 | W17: 7.1054274e-15 | X17: 0.41666667 | Y17: =IF(G17="Off","",IF(AND(G17>=TIME(9,0,0),G17<=TIME(10,0,0)),"early",IF(OR(G17=TIME(11,0,0),G17=TIME(12,0,0)),"late",""))) -> early | AA17: =IF(I17="Off","",IF(AND(I17>=TIME(9,0,0),I17<=TIME(10,0,0)),"early",IF(OR(I17=TIME(11,0,0),I17=TIME(12,0,0)),"late",""))) -> early
A18: 10316650 | B18: Hana Afifi | C18: CSR | D18: Production | E18: FT | F18: 2 | G18: 0.375 | H18: 0.79166667 | I18: 0.375 | J18: 0.79166667 | K18: 0.375 | L18: 0.79166667 | M18: 0.375 | N18: 0.79166667 | O18: OFF | P18: OFF | Q18: OFF | R18: OFF | S18: 0.45833333 | T18: 0.66666667 | U18: 45 | V18: 45 | W18: 7.1054274e-15 | X18: 0.41666667 | Y18: =IF(G18="Off","",IF(AND(G18>=TIME(9,0,0),G18<=TIME(10,0,0)),"early",IF(OR(G18=TIME(11,0,0),G18=TIME(12,0,0)),"late",""))) -> early | AA18: =IF(I18="Off","",IF(AND(I18>=TIME(9,0,0),I18<=TIME(10,0,0)),"early",IF(OR(I18=TIME(11,0,0),I18=TIME(12,0,0)),"late",""))) -> early
A19: 10316680 | B19: Hesham Hussien | C19: CSR | D19: Production | E19: FT | F19: 1 | G19: OFF | H19: OFF | I19: 0.45833333 | J19: 0.875 | K19: 0.45833333 | L19: 0.875 | M19: 0.45833333 | N19: 0.875 | O19: 0.45833333 | P19: 0.875 | Q19: 0.45833333 | R19: 0.66666667 | S19: OFF | T19: OFF | U19: 45 | V19: 45 | W19: -1.4210855e-14 | X19: 0.41666667 | Y19: =IF(G19="Off","",IF(AND(G19>=TIME(9,0,0),G19<=TIME(10,0,0)),"early",IF(OR(G19=TIME(11,0,0),G19=TIME(12,0,0)),"late",""))) | AA19: =IF(I19="Off","",IF(AND(I19>=TIME(9,0,0),I19<=TIME(10,0,0)),"early",IF(OR(I19=TIME(11,0,0),I19=TIME(12,0,0)),"late",""))) -> late
A20: 10316543 | B20: Khaled Zaafarany | C20: CSR | D20: Production | E20: FT | F20: 1 | G20: 0.45833333 | H20: 0.875 | I20: 0.45833333 | J20: 0.875 | K20: 0.45833333 | L20: 0.875 | M20: 0.45833333 | N20: 0.875 | O20: OFF | P20: OFF | Q20: OFF | R20: OFF | S20: 0.45833333 | T20: 0.66666667 | U20: 45 | V20: 45 | W20: -1.4210855e-14 | X20: 0.41666667 | Y20: =IF(G20="Off","",IF(AND(G20>=TIME(9,0,0),G20<=TIME(10,0,0)),"early",IF(OR(G20=TIME(11,0,0),G20=TIME(12,0,0)),"late",""))) -> late | AA20: =IF(I20="Off","",IF(AND(I20>=TIME(9,0,0),I20<=TIME(10,0,0)),"early",IF(OR(I20=TIME(11,0,0),I20=TIME(12,0,0)),"late",""))) -> late
A21: 10317153 | B21: Mahmoud Abdelaziz | C21: CSR | D21: Production | E21: FT | F21: 1 | G21: OFF | H21: OFF | I21: 0.375 | J21: 0.79166667 | K21: 0.375 | L21: 0.79166667 | M21: 0.375 | N21: 0.79166667 | O21: 0.375 | P21: 0.79166667 | Q21: 0.45833333 | R21: 0.66666667 | S21: OFF | T21: OFF | U21: 45 | V21: 45 | W21: -7.1054274e-15 | X21: 0.41666667 | Y21: =IF(G21="Off","",IF(AND(G21>=TIME(9,0,0),G21<=TIME(10,0,0)),"early",IF(OR(G21=TIME(11,0,0),G21=TIME(12,0,0)),"late",""))) | AA21: =IF(I21="Off","",IF(AND(I21>=TIME(9,0,0),I21<=TIME(10,0,0)),"early",IF(OR(I21=TIME(11,0,0),I21=TIME(12,0,0)),"late",""))) -> early
A22: 10252106 | B22: Marinass Elhusseni | C22: CSR | D22: Production | E22: FT | F22: 2 | G22: OFF | H22: OFF | I22: 0.375 | J22: 0.75 | K22: OFF | L22: OFF | M22: 0.375 | N22: 0.75 | O22: 0.375 | P22: 0.75 | Q22: 0.45833333 | R22: 0.66666667 | S22: 0.45833333 | T22: 0.66666667 | U22: 37 | V22: 37 | W22: 0 | X22: 0.375 | Y22: =IF(G22="Off","",IF(AND(G22>=TIME(9,0,0),G22<=TIME(10,0,0)),"early",IF(OR(G22=TIME(11,0,0),G22=TIME(12,0,0)),"late",""))) | AA22: =IF(I22="Off","",IF(AND(I22>=TIME(9,0,0),I22<=TIME(10,0,0)),"early",IF(OR(I22=TIME(11,0,0),I22=TIME(12,0,0)),"late",""))) -> early
A23: 10316538 | B23: Mohamed Abdelrahman | C23: CSR | D23: Production | E23: FT | F23: 1 | G23: 0.5 | H23: 0.875 | I23: 0.5 | J23: 0.875 | K23: OFF | L23: OFF | M23: OFF | N23: OFF | O23: 0.5 | P23: 0.875 | Q23: 0.45833333 | R23: 0.66666667 | S23: 0.45833333 | T23: 0.66666667 | U23: 37 | V23: 37 | W23: 0 | X23: 0.375 | Y23: =IF(G23="Off","",IF(AND(G23>=TIME(9,0,0),G23<=TIME(10,0,0)),"early",IF(OR(G23=TIME(11,0,0),G23=TIME(12,0,0)),"late",""))) -> late | AA23: =IF(I23="Off","",IF(AND(I23>=TIME(9,0,0),I23<=TIME(10,0,0)),"early",IF(OR(I23=TIME(11,0,0),I23=TIME(12,0,0)),"late",""))) -> late
A24: 10316545 | B24: Nada Mosbah | C24: CSR | D24: Production | E24: FT | F24: 1 | G24: OFF | H24: OFF | I24: 0.375 | J24: 0.79166667 | K24: 0.375 | L24: 0.79166667 | M24: 0.375 | N24: 0.79166667 | O24: 0.375 | P24: 0.79166667 | Q24: 0.45833333 | R24: 0.66666667 | S24: OFF | T24: OFF | U24: 45 | V24: 45 | W24: -7.1054274e-15 | X24: 0.41666667 | Y24: =IF(G24="Off","",IF(AND(G24>=TIME(9,0,0),G24<=TIME(10,0,0)),"early",IF(OR(G24=TIME(11,0,0),G24=TIME(12,0,0)),"late",""))) | AA24: =IF(I24="Off","",IF(AND(I24>=TIME(9,0,0),I24<=TIME(10,0,0)),"early",IF(OR(I24=TIME(11,0,0),I24=TIME(12,0,0)),"late",""))) -> early
A25: 10316572 | B25: Nadine Morsy | C25: CSR | D25: Production | E25: FT | F25: 2 | G25: 0.45833333 | H25: 0.875 | I25: 0.45833333 | J25: 0.875 | K25: 0.45833333 | L25: 0.875 | M25: 0.45833333 | N25: 0.875 | O25: OFF | P25: OFF | Q25: OFF | R25: OFF | S25: 0.45833333 | T25: 0.66666667 | U25: 45 | V25: 45 | W25: -1.4210855e-14 | X25: 0.41666667 | Y25: =IF(G25="Off","",IF(AND(G25>=TIME(9,0,0),G25<=TIME(10,0,0)),"early",IF(OR(G25=TIME(11,0,0),G25=TIME(12,0,0)),"late",""))) -> late | AA25: =IF(I25="Off","",IF(AND(I25>=TIME(9,0,0),I25<=TIME(10,0,0)),"early",IF(OR(I25=TIME(11,0,0),I25=TIME(12,0,0)),"late",""))) -> late
A26: 10316685 | B26: Nouran Noby | C26: CSR | D26: Production | E26: FT | F26: 1 | G26: OFF | H26: OFF | I26: 0.45833333 | J26: 0.875 | K26: 0.45833333 | L26: 0.875 | M26: 0.45833333 | N26: 0.875 | O26: 0.45833333 | P26: 0.875 | Q26: 0.45833333 | R26: 0.66666667 | S26: OFF | T26: OFF | U26: 45 | V26: 45 | W26: -1.4210855e-14 | X26: 0.41666667 | Y26: =IF(G26="Off","",IF(AND(G26>=TIME(9,0,0),G26<=TIME(10,0,0)),"early",IF(OR(G26=TIME(11,0,0),G26=TIME(12,0,0)),"late",""))) | AA26: =IF(I26="Off","",IF(AND(I26>=TIME(9,0,0),I26<=TIME(10,0,0)),"early",IF(OR(I26=TIME(11,0,0),I26=TIME(12,0,0)),"late",""))) -> late
A27: 10274446 | B27: Omar Eldeen | C27: CSR | D27: Production | E27: FT | F27: 2 | G27: 0.5 | H27: 0.875 | I27: 0.5 | J27: 0.875 | K27: OFF | L27: OFF | M27: OFF | N27: OFF | O27: 0.5 | P27: 0.875 | Q27: 0.45833333 | R27: 0.66666667 | S27: 0.45833333 | T27: 0.66666667 | U27: 37 | V27: 37 | W27: 0 | X27: 0.375 | Y27: =IF(G27="Off","",IF(AND(G27>=TIME(9,0,0),G27<=TIME(10,0,0)),"early",IF(OR(G27=TIME(11,0,0),G27=TIME(12,0,0)),"late",""))) -> late | AA27: =IF(I27="Off","",IF(AND(I27>=TIME(9,0,0),I27<=TIME(10,0,0)),"early",IF(OR(I27=TIME(11,0,0),I27=TIME(12,0,0)),"late",""))) -> late
A28: 10316546 | B28: Salma Majed | C28: CSR | D28: Production | E28: FT | F28: 1 | G28: 0.375 | H28: 0.79166667 | I28: 0.375 | J28: 0.79166667 | K28: 0.375 | L28: 0.79166667 | M28: 0.375 | N28: 0.79166667 | O28: OFF | P28: OFF | Q28: OFF | R28: OFF | S28: 0.45833333 | T28: 0.66666667 | U28: 45 | V28: 45 | W28: 7.1054274e-15 | X28: 0.41666667 | Y28: =IF(G28="Off","",IF(AND(G28>=TIME(9,0,0),G28<=TIME(10,0,0)),"early",IF(OR(G28=TIME(11,0,0),G28=TIME(12,0,0)),"late",""))) -> early | AA28: =IF(I28="Off","",IF(AND(I28>=TIME(9,0,0),I28<=TIME(10,0,0)),"early",IF(OR(I28=TIME(11,0,0),I28=TIME(12,0,0)),"late",""))) -> early
A29: 10316551 | B29: Salma Badreldin | C29: CSR | D29: Production | E29: FT | F29: 1 | G29: 0.375 | H29: 0.79166667 | I29: 0.375 | J29: 0.79166667 | K29: 0.375 | L29: 0.79166667 | M29: 0.375 | N29: 0.79166667 | O29: OFF | P29: OFF | Q29: OFF | R29: OFF | S29: 0.45833333 | T29: 0.66666667 | U29: 45 | V29: 45 | W29: 7.1054274e-15 | X29: 0.41666667 | Y29: =IF(G29="Off","",IF(AND(G29>=TIME(9,0,0),G29<=TIME(10,0,0)),"early",IF(OR(G29=TIME(11,0,0),G29=TIME(12,0,0)),"late",""))) -> early | AA29: =IF(I29="Off","",IF(AND(I29>=TIME(9,0,0),I29<=TIME(10,0,0)),"early",IF(OR(I29=TIME(11,0,0),I29=TIME(12,0,0)),"late",""))) -> early
A30: 10316683 | B30: Shahd Abdelaziz | C30: CSR | D30: Production | E30: FT | F30: 1 | G30: OFF | H30: OFF | I30: 0.375 | J30: 0.79166667 | K30: 0.375 | L30: 0.79166667 | M30: 0.375 | N30: 0.79166667 | O30: 0.375 | P30: 0.79166667 | Q30: 0.45833333 | R30: 0.66666667 | S30: OFF | T30: OFF | U30: 45 | V30: 45 | W30: 1.4210855e-14 | X30: 0.41666667 | Y30: =IF(G30="Off","",IF(AND(G30>=TIME(9,0,0),G30<=TIME(10,0,0)),"early",IF(OR(G30=TIME(11,0,0),G30=TIME(12,0,0)),"late",""))) | AA30: =IF(I30="Off","",IF(AND(I30>=TIME(9,0,0),I30<=TIME(10,0,0)),"early",IF(OR(I30=TIME(11,0,0),I30=TIME(12,0,0)),"late",""))) -> early
A31: 10317151 | B31: Youssef Shokry | C31: CSR | D31: Production | E31: FT | F31: 1 | G31: 0.375 | H31: 0.75 | I31: 0.375 | J31: 0.75 | K31: 0.375 | L31: 0.75 | M31: 0.375 | N31: 0.75 | O31: 0.375 | P31: 0.75 | Q31: OFF | R31: OFF | S31: OFF | T31: OFF | U31: 45 | V31: 45 | W31: 0 | X31: 0.41666667 | Y31: =IF(G31="Off","",IF(AND(G31>=TIME(9,0,0),G31<=TIME(10,0,0)),"early",IF(OR(G31=TIME(11,0,0),G31=TIME(12,0,0)),"late",""))) -> early | AA31: =IF(I31="Off","",IF(AND(I31>=TIME(9,0,0),I31<=TIME(10,0,0)),"early",IF(OR(I31=TIME(11,0,0),I31=TIME(12,0,0)),"late",""))) -> early
A32: 10317524 | B32: Zeina Ashraf | C32: CSR | D32: Production | E32: FT | F32: 2 | G32: 0.375 | H32: 0.75 | I32: 0.375 | J32: 0.75 | K32: 0.375 | L32: 0.75 | M32: 0.375 | N32: 0.75 | O32: 0.375 | P32: 0.75 | Q32: OFF | R32: OFF | S32: OFF | T32: OFF | U32: 45 | V32: 45 | W32: 0 | X32: 0.375 | Y32: =IF(G32="Off","",IF(AND(G32>=TIME(9,0,0),G32<=TIME(10,0,0)),"early",IF(OR(G32=TIME(11,0,0),G32=TIME(12,0,0)),"late",""))) -> early | AA32: =IF(I32="Off","",IF(AND(I32>=TIME(9,0,0),I32<=TIME(10,0,0)),"early",IF(OR(I32=TIME(11,0,0),I32=TIME(12,0,0)),"late",""))) -> early
A33: 10276839 | B33: Reem Alaa | C33: CSR | D33: Production | E33: FT | F33: 2 | G33: 0.375 | H33: 0.75 | I33: 0.375 | J33: 0.75 | K33: 0.375 | L33: 0.75 | M33: 0.375 | N33: 0.75 | O33: 0.375 | P33: 0.75 | Q33: OFF | R33: OFF | S33: OFF | T33: OFF | U33: 45 | V33: 45 | W33: 0 | X33: 0.375 | Y33: =IF(G33="Off","",IF(AND(G33>=TIME(9,0,0),G33<=TIME(10,0,0)),"early",IF(OR(G33=TIME(11,0,0),G33=TIME(12,0,0)),"late",""))) -> early | AA33: =IF(I33="Off","",IF(AND(I33>=TIME(9,0,0),I33<=TIME(10,0,0)),"early",IF(OR(I33=TIME(11,0,0),I33=TIME(12,0,0)),"late",""))) -> early
A34: 10320407 | B34: Marleen Francis | C34: CSR | D34: Production | E34: FT | F34: 3 | G34: 0.375 | H34: 0.75 | I34: 0.375 | J34: 0.75 | K34: 0.375 | L34: 0.75 | M34: 0.375 | N34: 0.75 | O34: 0.375 | P34: 0.75 | Q34: OFF | R34: OFF | S34: OFF | T34: OFF | U34: 45 | V34: 45 | AA34: =IF(I34="Off","",IF(AND(I34>=TIME(9,0,0),I34<=TIME(10,0,0)),"early",IF(OR(I34=TIME(11,0,0),I34=TIME(12,0,0)),"late",""))) -> early
A35: 10320408 | B35: Alaa Ali | C35: CSR | D35: Production | E35: FT | F35: 3 | G35: 0.375 | H35: 0.75 | I35: 0.375 | J35: 0.75 | K35: 0.375 | L35: 0.75 | M35: 0.375 | N35: 0.75 | O35: 0.375 | P35: 0.75 | Q35: OFF | R35: OFF | S35: OFF | T35: OFF | U35: 45 | V35: 45 | AA35: =IF(I35="Off","",IF(AND(I35>=TIME(9,0,0),I35<=TIME(10,0,0)),"early",IF(OR(I35=TIME(11,0,0),I35=TIME(12,0,0)),"late",""))) -> early
A36: 10320409 | B36: Youssef Eltokhy | C36: CSR | D36: Production | E36: FT | F36: 3 | G36: 0.375 | H36: 0.75 | I36: 0.375 | J36: 0.75 | K36: 0.375 | L36: 0.75 | M36: 0.375 | N36: 0.75 | O36: 0.375 | P36: 0.75 | Q36: OFF | R36: OFF | S36: OFF | T36: OFF | U36: 45 | V36: 45 | AA36: =IF(I36="Off","",IF(AND(I36>=TIME(9,0,0),I36<=TIME(10,0,0)),"early",IF(OR(I36=TIME(11,0,0),I36=TIME(12,0,0)),"late",""))) -> early
A37: 10320410 | B37: Abdelrahman Etman | C37: CSR | D37: Production | E37: FT | F37: 3 | G37: 0.375 | H37: 0.75 | I37: 0.375 | J37: 0.75 | K37: 0.375 | L37: 0.75 | M37: 0.375 | N37: 0.75 | O37: 0.375 | P37: 0.75 | Q37: OFF | R37: OFF | S37: OFF | T37: OFF | U37: 45 | V37: 45 | AA37: =IF(I37="Off","",IF(AND(I37>=TIME(9,0,0),I37<=TIME(10,0,0)),"early",IF(OR(I37=TIME(11,0,0),I37=TIME(12,0,0)),"late",""))) -> early
A38: 10320412 | B38: Bassant Amin | C38: CSR | D38: Production | E38: FT | F38: 3 | G38: 0.375 | H38: 0.75 | I38: 0.375 | J38: 0.75 | K38: 0.375 | L38: 0.75 | M38: 0.375 | N38: 0.75 | O38: 0.375 | P38: 0.75 | Q38: OFF | R38: OFF | S38: OFF | T38: OFF | U38: 45 | V38: 45 | AA38: =IF(I38="Off","",IF(AND(I38>=TIME(9,0,0),I38<=TIME(10,0,0)),"early",IF(OR(I38=TIME(11,0,0),I38=TIME(12,0,0)),"late",""))) -> early
A39: 10320413 | B39: Alaa Abdulshafi | C39: CSR | D39: Production | E39: FT | F39: 3 | G39: 0.375 | H39: 0.75 | I39: 0.375 | J39: 0.75 | K39: 0.375 | L39: 0.75 | M39: 0.375 | N39: 0.75 | O39: 0.375 | P39: 0.75 | Q39: OFF | R39: OFF | S39: OFF | T39: OFF | U39: 45 | V39: 45 | AA39: =IF(I39="Off","",IF(AND(I39>=TIME(9,0,0),I39<=TIME(10,0,0)),"early",IF(OR(I39=TIME(11,0,0),I39=TIME(12,0,0)),"late",""))) -> early
A40: 10250966 | B40: Jumana Ashraf | C40: CSR | D40: Production | E40: FT | F40: 3 | G40: 0.375 | H40: 0.75 | I40: 0.375 | J40: 0.75 | K40: 0.375 | L40: 0.75 | M40: 0.375 | N40: 0.75 | O40: 0.375 | P40: 0.75 | Q40: OFF | R40: OFF | S40: OFF | T40: OFF | U40: 45 | V40: 45 | AA40: =IF(I40="Off","",IF(AND(I40>=TIME(9,0,0),I40<=TIME(10,0,0)),"early",IF(OR(I40=TIME(11,0,0),I40=TIME(12,0,0)),"late",""))) -> early
...

Sheet Copy of WK 48
G1: 45621 | I1: 45622 | K1: 45623 | M1: 45624 | O1: 45625 | Q1: 45626 | S1: 45627
F2: Wave | G2: Monday | I2: Tuesday | K2: Wednesday | M2: Thursday | O2: Friday | Q2: Saturday | S2: Sunday
A3: CIM | B3: Agent Name | C3: Position | D3: Stage | E3: FT/PT | G3: From | H3: To | I3: From | J3: To | K3: From | L3: To | M3: From | N3: To | O3: From | P3: To | Q3: From | R3: To | S3: From | T3: To | U3: Working hours | V3: Preferred | W3: last week | X3: Delta | Y3: Pattern
A4: 10317524 | B4: Zeina Ashraf | C4: CSR | D4: Production | E4: {=_xlfn.XLOOKUP(A4,'Schedule Wk 47'!A:A,'Schedule Wk 47'!E:E,"")} -> FT | F4: {=_xlfn.XLOOKUP(A4,'Schedule Wk 47'!A:A,'Schedule Wk 47'!F:F,"")} -> 2 | G4: 0.375 | H4: =IFERROR(G4+$Y4,"OFF") -> 0.75 | I4: 0.375 | J4: =IFERROR(I4+$Y4,"OFF") -> 0.75 | K4: 0.375 | L4: =IFERROR(K4+$Y4,"OFF") -> 0.75 | M4: 0.375 | N4: =IFERROR(M4+$Y4,"OFF") -> 0.75 | O4: 0.375 | P4: =IFERROR(O4+$Y4,"OFF") -> 0.75 | Q4: OFF | R4: OFF | S4: OFF | T4: OFF | U4: =IFERROR(__xludf.DUMMYFUNCTION("TO_PURE_NUMBER(SUM(FILTER(G4:T4, ISEVEN(COLUMN(G4:T4))))-SUM(FILTER(G4:T4, ISODD(COLUMN(G4:T4)))))*24"),45) -> 45 | V4: {=_xlfn.XLOOKUP(A4,'WK 47'!A:A,'WK 47'!V:V,"")} -> 45 | W4: {=_xlfn.XLOOKUP(A4,'WK 47'!A:A,'WK 47'!AA:AA,"")} -> early | X4: =V4-U4 -> 0 | Y4: {=_xlfn.XLOOKUP(A4,'WK 45'!A:A,'WK 45'!X:X,"")} -> 0.375
A5: 10316683 | B5: Shahd Abdelaziz | C5: CSR | D5: Production | E5: {=_xlfn.XLOOKUP(A5,'Schedule Wk 47'!A:A,'Schedule Wk 47'!E:E,"")} -> FT | F5: {=_xlfn.XLOOKUP(A5,'Schedule Wk 47'!A:A,'Schedule Wk 47'!F:F,"")} -> 1 | G5: 0.375 | H5: =IFERROR(G5+$Y5,"OFF") -> 0.79166667 | I5: 0.375 | J5: =IFERROR(I5+$Y5,"OFF") -> 0.79166667 | K5: 0.375 | L5: =IFERROR(K5+$Y5,"OFF") -> 0.79166667 | M5: 0.375 | N5: =IFERROR(M5+$Y5,"OFF") -> 0.79166667 | O5: OFF | P5: OFF | Q5: OFF | R5: OFF | S5: 0.45833333 | T5: 0.66666667 | U5: =IFERROR(__xludf.DUMMYFUNCTION("TO_PURE_NUMBER(SUM(FILTER(G5:T5, ISEVEN(COLUMN(G5:T5))))-SUM(FILTER(G5:T5, ISODD(COLUMN(G5:T5)))))*24"),44.9999999999999) -> 45 | V5: {=_xlfn.XLOOKUP(A5,'WK 47'!A:A,'WK 47'!V:V,"")} -> 45 | W5: {=_xlfn.XLOOKUP(A5,'WK 47'!A:A,'WK 47'!AA:AA,"")} -> early | X5: =V5-U5 -> 9.9475983e-14 | Y5: {=_xlfn.XLOOKUP(A5,'WK 45'!A:A,'WK 45'!X:X,"")} -> 0.41666667
A6: 10320419 | B6: Salma Hassan | C6: CSR | D6: Production | E6: {=_xlfn.XLOOKUP(A6,'Schedule Wk 47'!A:A,'Schedule Wk 47'!E:E,"")} -> FT | F6: {=_xlfn.XLOOKUP(A6,'Schedule Wk 47'!A:A,'Schedule Wk 47'!F:F,"")} -> 3 | G6: OFF | H6: OFF | I6: 0.375 | J6: =IFERROR(I6+$Y6,"OFF") -> 0.79166667 | K6: 0.375 | L6: =IFERROR(K6+$Y6,"OFF") -> 0.79166667 | M6: 0.375 | N6: =IFERROR(M6+$Y6,"OFF") -> 0.79166667 | O6: 0.375 | P6: =IFERROR(O6+$Y6,"OFF") -> 0.79166667 | Q6: 0.45833333 | R6: 0.66666667 | S6: OFF | T6: OFF | U6: =IFERROR(__xludf.DUMMYFUNCTION("TO_PURE_NUMBER(SUM(FILTER(G6:T6, ISEVEN(COLUMN(G6:T6))))-SUM(FILTER(G6:T6, ISODD(COLUMN(G6:T6)))))*24"),44.9999999999999) -> 45 | V6: {=_xlfn.XLOOKUP(A6,'WK 47'!A:A,'WK 47'!V:V,"")} -> 45 | W6: {=_xlfn.XLOOKUP(A6,'WK 47'!A:A,'WK 47'!AA:AA,"")} -> early | X6: =V6-U6 -> 9.9475983e-14 | Y6: 0.41666667
A7: 10316572 | B7: Nadine Morsy | C7: CSR | D7: Production | E7: {=_xlfn.XLOOKUP(A7,'Schedule Wk 47'!A:A,'Schedule Wk 47'!E:E,"")} -> FT | F7: {=_xlfn.XLOOKUP(A7,'Schedule Wk 47'!A:A,'Schedule Wk 47'!F:F,"")} -> 2 | G7: 0.5 | H7: =IFERROR(G7+$Y7,"OFF") -> 0.875 | I7: 0.5 | J7: =IFERROR(I7+$Y7,"OFF") -> 0.875 | K7: 0.5 | L7: =IFERROR(K7+$Y7,"OFF") -> 0.875 | M7: 0.5 | N7: =IFERROR(M7+$Y7,"OFF") -> 0.875 | O7: 0.5 | P7: =IFERROR(O7+$Y7,"OFF") -> 0.875 | Q7: OFF | R7: OFF | S7: OFF | T7: OFF | U7: =IFERROR(__xludf.DUMMYFUNCTION("TO_PURE_NUMBER(SUM(FILTER(G7:T7, ISEVEN(COLUMN(G7:T7))))-SUM(FILTER(G7:T7, ISODD(COLUMN(G7:T7)))))*24"),45) -> 45 | V7: {=_xlfn.XLOOKUP(A7,'WK 47'!A:A,'WK 47'!V:V,"")} -> 45 | W7: {=_xlfn.XLOOKUP(A7,'WK 47'!A:A,'WK 47'!AA:AA,"")} -> late | X7: =V7-U7 -> 0 | Y7: {=_xlfn.XLOOKUP(A7,'WK 45'!A:A,'WK 45'!X:X,"")} -> 0.375
A8: 10316545 | B8: Nada Mosbah | C8: CSR | D8: Production | E8: {=_xlfn.XLOOKUP(A8,'Schedule Wk 47'!A:A,'Schedule Wk 47'!E:E,"")} -> FT | F8: {=_xlfn.XLOOKUP(A8,'Schedule Wk 47'!A:A,'Schedule Wk 47'!F:F,"")} -> 1 | G8: 0.375 | H8: 0.75 | I8: 0.375 | J8: 0.75 | K8: 0.375 | L8: 0.75 | M8: 0.375 | N8: 0.75 | O8: 0.375 | P8: 0.75 | Q8: OFF | R8: OFF | S8: OFF | T8: OFF | U8: =IFERROR(__xludf.DUMMYFUNCTION("TO_PURE_NUMBER(SUM(FILTER(G8:T8, ISEVEN(COLUMN(G8:T8))))-SUM(FILTER(G8:T8, ISODD(COLUMN(G8:T8)))))*24"),45) -> 45 | V8: {=_xlfn.XLOOKUP(A8,'WK 47'!A:A,'WK 47'!V:V,"")} -> 45 | W8: {=_xlfn.XLOOKUP(A8,'WK 47'!A:A,'WK 47'!AA:AA,"")} -> early | X8: =V8-U8 -> 0 | Y8: {=_xlfn.XLOOKUP(A8,'WK 45'!A:A,'WK 45'!X:X,"")} -> 0.41666667
A9: 10317517 | B9: Mariam Hanna | C9: CSR | D9: Production | E9: {=_xlfn.XLOOKUP(A9,'Schedule Wk 47'!A:A,'Schedule Wk 47'!E:E,"")} -> FT | F9: {=_xlfn.XLOOKUP(A9,'Schedule Wk 47'!A:A,'Schedule Wk 47'!F:F,"")} -> 2 | G9: 0.375 | H9: 0.79166667 | I9: 0.375 | J9: 0.79166667 | K9: 0.375 | L9: 0.79166667 | M9: 0.375 | N9: 0.79166667 | O9: OFF | P9: OFF | Q9: OFF | R9: OFF | S9: 0.45833333 | T9: 0.66666667 | U9: =IFERROR(__xludf.DUMMYFUNCTION("TO_PURE_NUMBER(SUM(FILTER(G9:T9, ISEVEN(COLUMN(G9:T9))))-SUM(FILTER(G9:T9, ISODD(COLUMN(G9:T9)))))*24"),44.9999999999999) -> 45 | V9: {=_xlfn.XLOOKUP(A9,'WK 47'!A:A,'WK 47'!V:V,"")} -> 45 | W9: {=_xlfn.XLOOKUP(A9,'WK 47'!A:A,'WK 47'!AA:AA,"")} -> early | X9: =V9-U9 -> 9.9475983e-14 | Y9: {=_xlfn.XLOOKUP(A9,'WK 45'!A:A,'WK 45'!X:X,"")} -> 0.375
A10: 10317521 | B10: Mariam Gadalkarim | C10: CSR | D10: Production | E10: {=_xlfn.XLOOKUP(A10,'Schedule Wk 47'!A:A,'Schedule Wk 47'!E:E,"")} -> FT | F10: {=_xlfn.XLOOKUP(A10,'Schedule Wk 47'!A:A,'Schedule Wk 47'!F:F,"")} -> 2 | G10: 0.375 | H10: 0.75 | I10: 0.375 | J10: 0.75 | K10: 0.375 | L10: 0.75 | M10: 0.375 | N10: 0.75 | O10: 0.375 | P10: 0.75 | Q10: OFF | R10: OFF | S10: OFF | T10: OFF | U10: =IFERROR(__xludf.DUMMYFUNCTION("TO_PURE_NUMBER(SUM(FILTER(G10:T10, ISEVEN(COLUMN(G10:T10))))-SUM(FILTER(G10:T10, ISODD(COLUMN(G10:T10)))))*24"),45) -> 45 | V10: {=_xlfn.XLOOKUP(A10,'WK 47'!A:A,'WK 47'!V:V,"")} -> 45 | W10: {=_xlfn.XLOOKUP(A10,'WK 47'!A:A,'WK 47'!AA:AA,"")} -> early | X10: =V10-U10 -> 0 | Y10: {=_xlfn.XLOOKUP(A10,'WK 45'!A:A,'WK 45'!X:X,"")} -> 0.375
A11: 10316680 | B11: Hesham Hussien | C11: CSR | D11: Production | E11: {=_xlfn.XLOOKUP(A11,'Schedule Wk 47'!A:A,'Schedule Wk 47'!E:E,"")} -> FT | F11: {=_xlfn.XLOOKUP(A11,'Schedule Wk 47'!A:A,'Schedule Wk 47'!F:F,"")} -> 1 | G11: OFF | H11: OFF | I11: 0.45833333 | J11: 0.875 | K11: 0.45833333 | L11: 0.875 | M11: 0.45833333 | N11: 0.875 | O11: 0.45833333 | P11: 0.875 | Q11: 0.45833333 | R11: 0.66666667 | S11: OFF | T11: OFF | U11: =IFERROR(__xludf.DUMMYFUNCTION("TO_PURE_NUMBER(SUM(FILTER(G11:T11, ISEVEN(COLUMN(G11:T11))))-SUM(FILTER(G11:T11, ISODD(COLUMN(G11:T11)))))*24"),45) -> 45 | V11: {=_xlfn.XLOOKUP(A11,'WK 47'!A:A,'WK 47'!V:V,"")} -> 45 | W11: {=_xlfn.XLOOKUP(A11,'WK 47'!A:A,'WK 47'!AA:AA,"")} -> late | X11: =V11-U11 -> 0 | Y11: {=_xlfn.XLOOKUP(A11,'WK 45'!A:A,'WK 45'!X:X,"")} -> 0.41666667
A12: 10320416 | B12: Hana Jankiz | C12: CSR | D12: Production | E12: {=_xlfn.XLOOKUP(A12,'Schedule Wk 47'!A:A,'Schedule Wk 47'!E:E,"")} -> FT | F12: {=_xlfn.XLOOKUP(A12,'Schedule Wk 47'!A:A,'Schedule Wk 47'!F:F,"")} -> 3 | G12: OFF | H12: OFF | I12: 0.375 | J12: 0.79166667 | K12: 0.375 | L12: 0.79166667 | M12: 0.375 | N12: 0.79166667 | O12: 0.375 | P12: 0.79166667 | Q12: 0.45833333 | R12: 0.66666667 | S12: OFF | T12: OFF | U12: =IFERROR(__xludf.DUMMYFUNCTION("TO_PURE_NUMBER(SUM(FILTER(G12:T12, ISEVEN(COLUMN(G12:T12))))-SUM(FILTER(G12:T12, ISODD(COLUMN(G12:T12)))))*24"),44.9999999999999) -> 45 | V12: {=_xlfn.XLOOKUP(A12,'WK 47'!A:A,'WK 47'!V:V,"")} -> 45 | W12: {=_xlfn.XLOOKUP(A12,'WK 47'!A:A,'WK 47'!AA:AA,"")} -> early | X12: =V12-U12 -> 9.9475983e-14 | Y12: {=_xlfn.XLOOKUP(A12,'WK 45'!A:A,'WK 45'!X:X,"")}
A13: 10316650 | B13: Hana Afifi | C13: CSR | D13: Production | E13: {=_xlfn.XLOOKUP(A13,'Schedule Wk 47'!A:A,'Schedule Wk 47'!E:E,"")} -> FT | F13: {=_xlfn.XLOOKUP(A13,'Schedule Wk 47'!A:A,'Schedule Wk 47'!F:F,"")} -> 2 | G13: 0.5 | H13: 0.875 | I13: 0.5 | J13: 0.875 | K13: 0.5 | L13: 0.875 | M13: 0.5 | N13: 0.875 | O13: 0.5 | P13: 0.875 | Q13: OFF | R13: OFF | S13: OFF | T13: OFF | U13: =IFERROR(__xludf.DUMMYFUNCTION("TO_PURE_NUMBER(SUM(FILTER(G13:T13, ISEVEN(COLUMN(G13:T13))))-SUM(FILTER(G13:T13, ISODD(COLUMN(G13:T13)))))*24"),45) -> 45 | V13: {=_xlfn.XLOOKUP(A13,'WK 47'!A:A,'WK 47'!V:V,"")} -> 45 | W13: {=_xlfn.XLOOKUP(A13,'WK 47'!A:A,'WK 47'!AA:AA,"")} -> early | X13: =V13-U13 -> 0 | Y13: {=_xlfn.XLOOKUP(A13,'WK 45'!A:A,'WK 45'!X:X,"")} -> 0.375
A14: 10317520 | B14: Farida Gadalkarim | C14: CSR | D14: Production | E14: {=_xlfn.XLOOKUP(A14,'Schedule Wk 47'!A:A,'Schedule Wk 47'!E:E,"")} -> FT | F14: {=_xlfn.XLOOKUP(A14,'Schedule Wk 47'!A:A,'Schedule Wk 47'!F:F,"")} -> 2 | G14: 0.375 | H14: 0.75 | I14: 0.375 | J14: 0.75 | K14: 0.375 | L14: 0.75 | M14: 0.375 | N14: 0.75 | O14: 0.375 | P14: 0.75 | Q14: OFF | R14: OFF | S14: OFF | T14: OFF | U14: =IFERROR(__xludf.DUMMYFUNCTION("TO_PURE_NUMBER(SUM(FILTER(G14:T14, ISEVEN(COLUMN(G14:T14))))-SUM(FILTER(G14:T14, ISODD(COLUMN(G14:T14)))))*24"),45) -> 45 | V14: {=_xlfn.XLOOKUP(A14,'WK 47'!A:A,'WK 47'!V:V,"")} -> 45 | W14: {=_xlfn.XLOOKUP(A14,'WK 47'!A:A,'WK 47'!AA:AA,"")} -> early | X14: =V14-U14 -> 0 | Y14: {=_xlfn.XLOOKUP(A14,'WK 45'!A:A,'WK 45'!X:X,"")} -> 0.375
A15: 10317147 | B15: Asalla Metwally | C15: CSR | D15: Production | E15: {=_xlfn.XLOOKUP(A15,'Schedule Wk 47'!A:A,'Schedule Wk 47'!E:E,"")} -> FT | F15: {=_xlfn.XLOOKUP(A15,'Schedule Wk 47'!A:A,'Schedule Wk 47'!F:F,"")} -> 1 | G15: OFF | H15: OFF | I15: 0.45833333 | J15: 0.875 | K15: 0.45833333 | L15: 0.875 | M15: 0.45833333 | N15: 0.875 | O15: 0.45833333 | P15: 0.875 | Q15: 0.45833333 | R15: 0.66666667 | S15: OFF | T15: OFF | U15: =IFERROR(__xludf.DUMMYFUNCTION("TO_PURE_NUMBER(SUM(FILTER(G15:T15, ISEVEN(COLUMN(G15:T15))))-SUM(FILTER(G15:T15, ISODD(COLUMN(G15:T15)))))*24"),45) -> 45 | V15: {=_xlfn.XLOOKUP(A15,'WK 47'!A:A,'WK 47'!V:V,"")} -> 45 | W15: {=_xlfn.XLOOKUP(A15,'WK 47'!A:A,'WK 47'!AA:AA,"")} -> early | X15: =V15-U15 -> 0 | Y15: {=_xlfn.XLOOKUP(A15,'WK 45'!A:A,'WK 45'!X:X,"")} -> 0.41666667
A16: 10320413 | B16: Alaa Abdulshafi | C16: CSR | D16: Production | E16: {=_xlfn.XLOOKUP(A16,'Schedule Wk 47'!A:A,'Schedule Wk 47'!E:E,"")} -> FT | F16: {=_xlfn.XLOOKUP(A16,'Schedule Wk 47'!A:A,'Schedule Wk 47'!F:F,"")} -> 3 | G16: OFF | H16: OFF | I16: 0.375 | J16: 0.79166667 | K16: 0.375 | L16: 0.79166667 | M16: 0.375 | N16: 0.79166667 | O16: 0.375 | P16: 0.79166667 | Q16: 0.45833333 | R16: 0.66666667 | S16: OFF | T16: OFF | U16: =IFERROR(__xludf.DUMMYFUNCTION("TO_PURE_NUMBER(SUM(FILTER(G16:T16, ISEVEN(COLUMN(G16:T16))))-SUM(FILTER(G16:T16, ISODD(COLUMN(G16:T16)))))*24"),44.9999999999999) -> 45 | V16: {=_xlfn.XLOOKUP(A16,'WK 47'!A:A,'WK 47'!V:V,"")} -> 45 | W16: {=_xlfn.XLOOKUP(A16,'WK 47'!A:A,'WK 47'!AA:AA,"")} -> early | X16: =V16-U16 -> 9.9475983e-14 | Y16: {=_xlfn.XLOOKUP(A16,'WK 45'!A:A,'WK 45'!X:X,"")}
A17: 10317522 | B17: Ahmed Hisham | C17: CSR | D17: Production | E17: {=_xlfn.XLOOKUP(A17,'Schedule Wk 47'!A:A,'Schedule Wk 47'!E:E,"")} -> FT | F17: {=_xlfn.XLOOKUP(A17,'Schedule Wk 47'!A:A,'Schedule Wk 47'!F:F,"")} -> 2 | G17: OFF | H17: OFF | I17: 0.45833333 | J17: 0.875 | K17: 0.45833333 | L17: 0.875 | M17: 0.45833333 | N17: 0.875 | O17: 0.45833333 | P17: 0.875 | Q17: 0.45833333 | R17: 0.66666667 | S17: OFF | T17: OFF | U17: =IFERROR(__xludf.DUMMYFUNCTION("TO_PURE_NUMBER(SUM(FILTER(G17:T17, ISEVEN(COLUMN(G17:T17))))-SUM(FILTER(G17:T17, ISODD(COLUMN(G17:T17)))))*24"),45) -> 45 | V17: {=_xlfn.XLOOKUP(A17,'WK 47'!A:A,'WK 47'!V:V,"")} -> 45 | W17: {=_xlfn.XLOOKUP(A17,'WK 47'!A:A,'WK 47'!AA:AA,"")} -> late | X17: =V17-U17 -> 0 | Y17: {=_xlfn.XLOOKUP(A17,'WK 45'!A:A,'WK 45'!X:X,"")} -> 0.375
A18: 10317151 | B18: Youssef Shokry | C18: CSR | D18: B2B | E18: {=_xlfn.XLOOKUP(A18,'Schedule Wk 47'!A:A,'Schedule Wk 47'!E:E,"")} -> FT | F18: {=_xlfn.XLOOKUP(A18,'Schedule Wk 47'!A:A,'Schedule Wk 47'!F:F,"")} -> 1 | G18: 0.375 | H18: 0.75 | I18: 0.375 | J18: 0.75 | K18: 0.375 | L18: 0.75 | M18: 0.375 | N18: 0.75 | O18: 0.375 | P18: 0.75 | Q18: OFF | R18: OFF | S18: OFF | T18: OFF | U18: =IFERROR(__xludf.DUMMYFUNCTION("TO_PURE_NUMBER(SUM(FILTER(G18:T18, ISEVEN(COLUMN(G18:T18))))-SUM(FILTER(G18:T18, ISODD(COLUMN(G18:T18)))))*24"),45) -> 45 | V18: {=_xlfn.XLOOKUP(A18,'WK 47'!A:A,'WK 47'!V:V,"")} -> 45 | W18: {=_xlfn.XLOOKUP(A18,'WK 47'!A:A,'WK 47'!AA:AA,"")} -> early | X18: =V18-U18 -> 0 | Y18: {=_xlfn.XLOOKUP(A18,'WK 45'!A:A,'WK 45'!X:X,"")} -> 0.41666667
A19: 10320409 | B19: Youssef Eltokhy | C19: CSR | D19: Production | E19: {=_xlfn.XLOOKUP(A19,'Schedule Wk 47'!A:A,'Schedule Wk 47'!E:E,"")} -> FT | F19: {=_xlfn.XLOOKUP(A19,'Schedule Wk 47'!A:A,'Schedule Wk 47'!F:F,"")} -> 3 | G19: 0.375 | H19: 0.75 | I19: 0.375 | J19: 0.75 | K19: 0.375 | L19: 0.75 | M19: 0.375 | N19: 0.75 | O19: 0.375 | P19: 0.75 | Q19: OFF | R19: OFF | S19: OFF | T19: OFF | U19: =IFERROR(__xludf.DUMMYFUNCTION("TO_PURE_NUMBER(SUM(FILTER(G19:T19, ISEVEN(COLUMN(G19:T19))))-SUM(FILTER(G19:T19, ISODD(COLUMN(G19:T19)))))*24"),45) -> 45 | V19: {=_xlfn.XLOOKUP(A19,'WK 47'!A:A,'WK 47'!V:V,"")} -> 45 | W19: {=_xlfn.XLOOKUP(A19,'WK 47'!A:A,'WK 47'!AA:AA,"")} -> early | X19: =V19-U19 -> 0 | Y19: {=_xlfn.XLOOKUP(A19,'WK 45'!A:A,'WK 45'!X:X,"")}
A20: 10293627 | B20: Yassin shaker | C20: CSR | D20: Production | E20: {=_xlfn.XLOOKUP(A20,'Schedule Wk 47'!A:A,'Schedule Wk 47'!E:E,"")} -> FT | F20: {=_xlfn.XLOOKUP(A20,'Schedule Wk 47'!A:A,'Schedule Wk 47'!F:F,"")} -> 3 | G20: 0.375 | H20: 0.75 | I20: 0.375 | J20: 0.75 | K20: 0.375 | L20: 0.75 | M20: 0.375 | N20: 0.75 | O20: 0.375 | P20: 0.75 | Q20: OFF | R20: OFF | S20: OFF | T20: OFF | U20: =IFERROR(__xludf.DUMMYFUNCTION("TO_PURE_NUMBER(SUM(FILTER(G20:T20, ISEVEN(COLUMN(G20:T20))))-SUM(FILTER(G20:T20, ISODD(COLUMN(G20:T20)))))*24"),45) -> 45 | V20: {=_xlfn.XLOOKUP(A20,'WK 47'!A:A,'WK 47'!V:V,"")} -> 45 | W20: {=_xlfn.XLOOKUP(A20,'WK 47'!A:A,'WK 47'!AA:AA,"")} -> early | X20: =V20-U20 -> 0 | Y20: 0.41666667
A21: 10316540 | B21: Wafaa Elnaby | C21: CSR | D21: B2B | E21: {=_xlfn.XLOOKUP(A21,'Schedule Wk 47'!A:A,'Schedule Wk 47'!E:E,"")} -> FT | F21: {=_xlfn.XLOOKUP(A21,'Schedule Wk 47'!A:A,'Schedule Wk 47'!F:F,"")} -> 1 | G21: 0.375 | H21: 0.75 | I21: 0.375 | J21: 0.75 | K21: 0.375 | L21: 0.75 | M21: 0.375 | N21: 0.75 | O21: 0.375 | P21: 0.75 | Q21: OFF | R21: OFF | S21: OFF | T21: OFF | U21: =IFERROR(__xludf.DUMMYFUNCTION("TO_PURE_NUMBER(SUM(FILTER(G21:T21, ISEVEN(COLUMN(G21:T21))))-SUM(FILTER(G21:T21, ISODD(COLUMN(G21:T21)))))*24"),45) -> 45 | V21: {=_xlfn.XLOOKUP(A21,'WK 47'!A:A,'WK 47'!V:V,"")} -> 45 | W21: {=_xlfn.XLOOKUP(A21,'WK 47'!A:A,'WK 47'!AA:AA,"")} -> late | X21: =V21-U21 -> 0 | Y21: {=_xlfn.XLOOKUP(A21,'WK 45'!A:A,'WK 45'!X:X,"")} -> 0.41666667
A22: 10320435 | B22: Seifeldin Hassan | C22: CSR | D22: Production | E22: {=_xlfn.XLOOKUP(A22,'Schedule Wk 47'!A:A,'Schedule Wk 47'!E:E,"")} -> FT | F22: {=_xlfn.XLOOKUP(A22,'Schedule Wk 47'!A:A,'Schedule Wk 47'!F:F,"")} -> 3 | G22: 0.375 | H22: 0.75 | I22: 0.375 | J22: 0.75 | K22: 0.375 | L22: 0.75 | M22: 0.375 | N22: 0.75 | O22: 0.375 | P22: 0.75 | Q22: OFF | R22: OFF | S22: OFF | T22: OFF | U22: =IFERROR(__xludf.DUMMYFUNCTION("TO_PURE_NUMBER(SUM(FILTER(G22:T22, ISEVEN(COLUMN(G22:T22))))-SUM(FILTER(G22:T22, ISODD(COLUMN(G22:T22)))))*24"),45) -> 45 | V22: {=_xlfn.XLOOKUP(A22,'WK 47'!A:A,'WK 47'!V:V,"")} -> 45 | W22: {=_xlfn.XLOOKUP(A22,'WK 47'!A:A,'WK 47'!AA:AA,"")} -> early | X22: =V22-U22 -> 0 | Y22: {=_xlfn.XLOOKUP(A22,'WK 45'!A:A,'WK 45'!X:X,"")}
A23: 10316551 | B23: Salma Salah | C23: CSR | D23: Production | E23: {=_xlfn.XLOOKUP(A23,'Schedule Wk 47'!A:A,'Schedule Wk 47'!E:E,"")} -> FT | F23: {=_xlfn.XLOOKUP(A23,'Schedule Wk 47'!A:A,'Schedule Wk 47'!F:F,"")} -> 1 | G23: 0.5 | H23: 0.875 | I23: 0.5 | J23: 0.875 | K23: OFF | L23: OFF | M23: OFF | N23: OFF | O23: 0.5 | P23: 0.875 | Q23: 0.45833333 | R23: 0.66666667 | S23: 0.45833333 | T23: 0.66666667 | U23: =IFERROR(__xludf.DUMMYFUNCTION("TO_PURE_NUMBER(SUM(FILTER(G23:T23, ISEVEN(COLUMN(G23:T23))))-SUM(FILTER(G23:T23, ISODD(COLUMN(G23:T23)))))*24"),37) -> 37 | V23: {=_xlfn.XLOOKUP(A23,'WK 47'!A:A,'WK 47'!V:V,"")} -> 45 | W23: {=_xlfn.XLOOKUP(A23,'WK 47'!A:A,'WK 47'!AA:AA,"")} -> early | X23: =V23-U23 -> 8 | Y23: 0.41666667
A24: 10316546 | B24: Salma Majed | C24: CSR | D24: Production | E24: {=_xlfn.XLOOKUP(A24,'Schedule Wk 47'!A:A,'Schedule Wk 47'!E:E,"")} -> FT | F24: {=_xlfn.XLOOKUP(A24,'Schedule Wk 47'!A:A,'Schedule Wk 47'!F:F,"")} -> 1 | G24: 0.5 | H24: 0.875 | I24: 0.5 | J24: 0.875 | K24: 0.5 | L24: 0.875 | M24: OFF | N24: OFF | O24: OFF | P24: OFF | Q24: 0.45833333 | R24: 0.66666667 | S24: 0.45833333 | T24: 0.66666667 | U24: =IFERROR(__xludf.DUMMYFUNCTION("TO_PURE_NUMBER(SUM(FILTER(G24:T24, ISEVEN(COLUMN(G24:T24))))-SUM(FILTER(G24:T24, ISODD(COLUMN(G24:T24)))))*24"),37) -> 37 | V24: 37 | W24: {=_xlfn.XLOOKUP(A24,'WK 47'!A:A,'WK 47'!AA:AA,"")} -> early | X24: =V24-U24 -> 0 | Y24: 0.375
A25: 10276839 | B25: Reem Alaa | C25: CSR | D25: Production | E25: {=_xlfn.XLOOKUP(A25,'Schedule Wk 47'!A:A,'Schedule Wk 47'!E:E,"")} -> FT | F25: {=_xlfn.XLOOKUP(A25,'Schedule Wk 47'!A:A,'Schedule Wk 47'!F:F,"")} -> 2 | G25: 0.375 | H25: 0.79166667 | I25: 0.375 | J25: 0.79166667 | K25: 0.375 | L25: 0.79166667 | M25: 0.375 | N25: 0.79166667 | O25: OFF | P25: OFF | Q25: OFF | R25: OFF | S25: 0.45833333 | T25: 0.66666667 | U25: =IFERROR(__xludf.DUMMYFUNCTION("TO_PURE_NUMBER(SUM(FILTER(G25:T25, ISEVEN(COLUMN(G25:T25))))-SUM(FILTER(G25:T25, ISODD(COLUMN(G25:T25)))))*24"),44.9999999999999) -> 45 | V25: {=_xlfn.XLOOKUP(A25,'WK 47'!A:A,'WK 47'!V:V,"")} -> 45 | W25: {=_xlfn.XLOOKUP(A25,'WK 47'!A:A,'WK 47'!AA:AA,"")} -> early | X25: =V25-U25 -> 9.9475983e-14 | Y25: {=_xlfn.XLOOKUP(A25,'WK 45'!A:A,'WK 45'!X:X,"")} -> 0.375
A26: 10274446 | B26: Omar Emad | C26: CSR | D26: Production | E26: {=_xlfn.XLOOKUP(A26,'Schedule Wk 47'!A:A,'Schedule Wk 47'!E:E,"")} -> FT | F26: {=_xlfn.XLOOKUP(A26,'Schedule Wk 47'!A:A,'Schedule Wk 47'!F:F,"")} -> 2 | G26: 0.5 | H26: 0.875 | I26: OFF | J26: OFF | K26: OFF | L26: OFF | M26: 0.5 | N26: 0.875 | O26: 0.5 | P26: 0.875 | Q26: 0.45833333 | R26: 0.66666667 | S26: 0.45833333 | T26: 0.66666667 | U26: =IFERROR(__xludf.DUMMYFUNCTION("TO_PURE_NUMBER(SUM(FILTER(G26:T26, ISEVEN(COLUMN(G26:T26))))-SUM(FILTER(G26:T26, ISODD(COLUMN(G26:T26)))))*24"),37) -> 37 | V26: 37 | W26: {=_xlfn.XLOOKUP(A26,'WK 47'!A:A,'WK 47'!AA:AA,"")} -> late | X26: =V26-U26 -> 0 | Y26: 0.375
A27: 10316685 | B27: Nouran Noby | C27: Esc Mgr | D27: Production | E27: {=_xlfn.XLOOKUP(A27,'Schedule Wk 47'!A:A,'Schedule Wk 47'!E:E,"")} -> FT | F27: {=_xlfn.XLOOKUP(A27,'Schedule Wk 47'!A:A,'Schedule Wk 47'!F:F,"")} -> 1 | G27: 0.375 | H27: 0.75 | I27: 0.375 | J27: 0.75 | K27: 0.375 | L27: 0.75 | M27: 0.375 | N27: 0.75 | O27: 0.375 | P27: 0.75 | Q27: OFF | R27: OFF | S27: OFF | T27: OFF | U27: =IFERROR(__xludf.DUMMYFUNCTION("TO_PURE_NUMBER(SUM(FILTER(G27:T27, ISEVEN(COLUMN(G27:T27))))-SUM(FILTER(G27:T27, ISODD(COLUMN(G27:T27)))))*24"),45) -> 45 | V27: {=_xlfn.XLOOKUP(A27,'WK 47'!A:A,'WK 47'!V:V,"")} -> 45 | W27: {=_xlfn.XLOOKUP(A27,'WK 47'!A:A,'WK 47'!AA:AA,"")} -> late | X27: =V27-U27 -> 0 | Y27: {=_xlfn.XLOOKUP(A27,'WK 45'!A:A,'WK 45'!X:X,"")} -> 0.41666667
A28: 10293607 | B28: Mohamed Hassan | C28: CSR | D28: Production | E28: {=_xlfn.XLOOKUP(A28,'Schedule Wk 47'!A:A,'Schedule Wk 47'!E:E,"")} -> FT | F28: {=_xlfn.XLOOKUP(A28,'Schedule Wk 47'!A:A,'Schedule Wk 47'!F:F,"")} -> 3 | G28: 0.375 | H28: 0.75 | I28: 0.375 | J28: 0.75 | K28: 0.375 | L28: 0.75 | M28: 0.375 | N28: 0.75 | O28: 0.375 | P28: 0.75 | Q28: OFF | R28: OFF | S28: OFF | T28: OFF | U28: =IFERROR(__xludf.DUMMYFUNCTION("TO_PURE_NUMBER(SUM(FILTER(G28:T28, ISEVEN(COLUMN(G28:T28))))-SUM(FILTER(G28:T28, ISODD(COLUMN(G28:T28)))))*24"),45) -> 45 | V28: {=_xlfn.XLOOKUP(A28,'WK 47'!A:A,'WK 47'!V:V,"")} -> 45 | W28: {=_xlfn.XLOOKUP(A28,'WK 47'!A:A,'WK 47'!AA:AA,"")} -> early | X28: =V28-U28 -> 0 | Y28: {=_xlfn.XLOOKUP(A28,'WK 45'!A:A,'WK 45'!X:X,"")}
A29: 10316538 | B29: Mohamed Abdelrahman | C29: CSR | D29: Production | E29: {=_xlfn.XLOOKUP(A29,'Schedule Wk 47'!A:A,'Schedule Wk 47'!E:E,"")} -> FT | F29: {=_xlfn.XLOOKUP(A29,'Schedule Wk 47'!A:A,'Schedule Wk 47'!F:F,"")} -> 1 | G29: 0.5 | H29: 0.875 | I29: 0.5 | J29: 0.875 | K29: OFF | L29: OFF | M29: OFF | N29: OFF | O29: 0.5 | P29: 0.875 | Q29: 0.45833333 | R29: 0.66666667 | S29: 0.45833333 | T29: 0.66666667 | U29: =IFERROR(__xludf.DUMMYFUNCTION("TO_PURE_NUMBER(SUM(FILTER(G29:T29, ISEVEN(COLUMN(G29:T29))))-SUM(FILTER(G29:T29, ISODD(COLUMN(G29:T29)))))*24"),37) -> 37 | V29: {=_xlfn.XLOOKUP(A29,'WK 47'!A:A,'WK 47'!V:V,"")} -> 37 | W29: {=_xlfn.XLOOKUP(A29,'WK 47'!A:A,'WK 47'!AA:AA,"")} -> late | X29: =V29-U29 -> 0 | Y29: {=_xlfn.XLOOKUP(A29,'WK 45'!A:A,'WK 45'!X:X,"")} -> 0.41666667
A30: 10320436 | B30: Mazen Shoukry | C30: CSR | D30: Production | E30: {=_xlfn.XLOOKUP(A30,'Schedule Wk 47'!A:A,'Schedule Wk 47'!E:E,"")} -> FT | F30: {=_xlfn.XLOOKUP(A30,'Schedule Wk 47'!A:A,'Schedule Wk 47'!F:F,"")} -> 3 | G30: 0.375 | H30: 0.75 | I30: 0.375 | J30: 0.75 | K30: 0.375 | L30: 0.75 | M30: 0.375 | N30: 0.75 | O30: 0.375 | P30: 0.75 | Q30: OFF | R30: OFF | S30: OFF | T30: OFF | U30: =IFERROR(__xludf.DUMMYFUNCTION("TO_PURE_NUMBER(SUM(FILTER(G30:T30, ISEVEN(COLUMN(G30:T30))))-SUM(FILTER(G30:T30, ISODD(COLUMN(G30:T30)))))*24"),45) -> 45 | V30: {=_xlfn.XLOOKUP(A30,'WK 47'!A:A,'WK 47'!V:V,"")} -> 45 | W30: {=_xlfn.XLOOKUP(A30,'WK 47'!A:A,'WK 47'!AA:AA,"")} -> early | X30: =V30-U30 -> 0 | Y30: {=_xlfn.XLOOKUP(A30,'WK 45'!A:A,'WK 45'!X:X,"")}
A31: 10317154 | B31: Mazen Elramlawy | C31: CSR | D31: Production | E31: {=_xlfn.XLOOKUP(A31,'Schedule Wk 47'!A:A,'Schedule Wk 47'!E:E,"")} -> FT | F31: {=_xlfn.XLOOKUP(A31,'Schedule Wk 47'!A:A,'Schedule Wk 47'!F:F,"")} -> 3 | G31: 0.375 | H31: 0.75 | I31: 0.375 | J31: 0.75 | K31: 0.375 | L31: 0.75 | M31: 0.375 | N31: 0.75 | O31: 0.375 | P31: 0.75 | Q31: OFF | R31: OFF | S31: OFF | T31: OFF | U31: =IFERROR(__xludf.DUMMYFUNCTION("TO_PURE_NUMBER(SUM(FILTER(G31:T31, ISEVEN(COLUMN(G31:T31))))-SUM(FILTER(G31:T31, ISODD(COLUMN(G31:T31)))))*24"),45) -> 45 | V31: {=_xlfn.XLOOKUP(A31,'WK 47'!A:A,'WK 47'!V:V,"")} -> 45 | W31: {=_xlfn.XLOOKUP(A31,'WK 47'!A:A,'WK 47'!AA:AA,"")} -> early | X31: =V31-U31 -> 0 | Y31: {=_xlfn.XLOOKUP(A31,'WK 45'!A:A,'WK 45'!X:X,"")}
A32: 10320417 | B32: Marwa Nofal | C32: CSR | D32: Production | E32: {=_xlfn.XLOOKUP(A32,'Schedule Wk 47'!A:A,'Schedule Wk 47'!E:E,"")} -> FT | F32: {=_xlfn.XLOOKUP(A32,'Schedule Wk 47'!A:A,'Schedule Wk 47'!F:F,"")} -> 3 | G32: 0.375 | H32: 0.75 | I32: 0.375 | J32: 0.75 | K32: 0.375 | L32: 0.75 | M32: 0.375 | N32: 0.75 | O32: 0.375 | P32: 0.75 | Q32: OFF | R32: OFF | S32: OFF | T32: OFF | U32: =IFERROR(__xludf.DUMMYFUNCTION("TO_PURE_NUMBER(SUM(FILTER(G32:T32, ISEVEN(COLUMN(G32:T32))))-SUM(FILTER(G32:T32, ISODD(COLUMN(G32:T32)))))*24"),45) -> 45 | V32: {=_xlfn.XLOOKUP(A32,'WK 47'!A:A,'WK 47'!V:V,"")} -> 45 | W32: {=_xlfn.XLOOKUP(A32,'WK 47'!A:A,'WK 47'!AA:AA,"")} -> early | X32: =V32-U32 -> 0 | Y32: 0.20833333
A33: 10320407 | B33: Marleen Francis | C33: CSR | D33: Production | E33: {=_xlfn.XLOOKUP(A33,'Schedule Wk 47'!A:A,'Schedule Wk 47'!E:E,"")} -> FT | F33: {=_xlfn.XLOOKUP(A33,'Schedule Wk 47'!A:A,'Schedule Wk 47'!F:F,"")} -> 3 | G33: 0.375 | H33: 0.75 | I33: 0.375 | J33: 0.75 | K33: 0.375 | L33: 0.75 | M33: 0.375 | N33: 0.75 | O33: 0.375 | P33: 0.75 | Q33: OFF | R33: OFF | S33: OFF | T33: OFF | U33: =IFERROR(__xludf.DUMMYFUNCTION("TO_PURE_NUMBER(SUM(FILTER(G33:T33, ISEVEN(COLUMN(G33:T33))))-SUM(FILTER(G33:T33, ISODD(COLUMN(G33:T33)))))*24"),45) -> 45 | V33: {=_xlfn.XLOOKUP(A33,'WK 47'!A:A,'WK 47'!V:V,"")} -> 45 | W33: {=_xlfn.XLOOKUP(A33,'WK 47'!A:A,'WK 47'!AA:AA,"")} -> early | X33: =V33-U33 -> 0 | Y33: {=_xlfn.XLOOKUP(A33,Pref!A:A,Pref!E:E,"")} -> 10 hours (4 weekdays) + 5 hours (1 weekends) (45hrs/Week)
A34: 10252106 | B34: Marinass Elhusseni | C34: CSR | D34: Production | E34: {=_xlfn.XLOOKUP(A34,'Schedule Wk 47'!A:A,'Schedule Wk 47'!E:E,"")} -> FT | F34: {=_xlfn.XLOOKUP(A34,'Schedule Wk 47'!A:A,'Schedule Wk 47'!F:F,"")} -> 2 | G34: OFF | H34: OFF | I34: 0.375 | J34: 0.75 | K34: OFF | L34: OFF | M34: 0.375 | N34: 0.75 | O34: 0.375 | P34: 0.75 | Q34: 0.45833333 | R34: 0.66666667 | S34: 0.45833333 | T34: 0.66666667 | U34: =IFERROR(__xludf.DUMMYFUNCTION("TO_PURE_NUMBER(SUM(FILTER(G34:T34, ISEVEN(COLUMN(G34:T34))))-SUM(FILTER(G34:T34, ISODD(COLUMN(G34:T34)))))*24"),37) -> 37 | V34: {=_xlfn.XLOOKUP(A34,'WK 47'!A:A,'WK 47'!V:V,"")} -> 37 | W34: {=_xlfn.XLOOKUP(A34,'WK 47'!A:A,'WK 47'!AA:AA,"")} -> early | X34: =V34-U34 -> 0 | Y34: 0.375
A35: 10317153 | B35: Mahmoud Abdelaziz | C35: CSR | D35: Production | E35: {=_xlfn.XLOOKUP(A35,'Schedule Wk 47'!A:A,'Schedule Wk 47'!E:E,"")} -> FT | F35: {=_xlfn.XLOOKUP(A35,'Schedule Wk 47'!A:A,'Schedule Wk 47'!F:F,"")} -> 1 | G35: OFF | H35: OFF | I35: 0.375 | J35: 0.75 | K35: 0.375 | L35: 0.75 | M35: 0.375 | N35: 0.75 | O35: 0.375 | P35: 0.79166667 | Q35: 0.45833333 | R35: 0.66666667 | S35: OFF | T35: OFF | U35: =IFERROR(__xludf.DUMMYFUNCTION("TO_PURE_NUMBER(SUM(FILTER(G35:T35, ISEVEN(COLUMN(G35:T35))))-SUM(FILTER(G35:T35, ISODD(COLUMN(G35:T35)))))*24"),41.9999999999999) -> 42 | V35: {=_xlfn.XLOOKUP(A35,'WK 47'!A:A,'WK 47'!V:V,"")} -> 45 | W35: {=_xlfn.XLOOKUP(A35,'WK 47'!A:A,'WK 47'!AA:AA,"")} -> early | X35: =V35-U35 -> 3 | Y35: 0.41666667
A36: 10316543 | B36: Khaled Zaafarany | C36: CSR | D36: Production | E36: {=_xlfn.XLOOKUP(A36,'Schedule Wk 47'!A:A,'Schedule Wk 47'!E:E,"")} -> FT | F36: {=_xlfn.XLOOKUP(A36,'Schedule Wk 47'!A:A,'Schedule Wk 47'!F:F,"")} -> 1 | G36: 0.45833333 | H36: 0.875 | I36: 0.45833333 | J36: 0.875 | K36: 0.45833333 | L36: 0.875 | M36: 0.45833333 | N36: 0.875 | O36: OFF | P36: OFF | Q36: OFF | R36: OFF | S36: 0.45833333 | T36: 0.66666667 | U36: =IFERROR(__xludf.DUMMYFUNCTION("TO_PURE_NUMBER(SUM(FILTER(G36:T36, ISEVEN(COLUMN(G36:T36))))-SUM(FILTER(G36:T36, ISODD(COLUMN(G36:T36)))))*24"),45) -> 45 | V36: {=_xlfn.XLOOKUP(A36,'WK 47'!A:A,'WK 47'!V:V,"")} -> 45 | W36: {=_xlfn.XLOOKUP(A36,'WK 47'!A:A,'WK 47'!AA:AA,"")} -> late | X36: =V36-U36 -> 0 | Y36: 0.41666667
A37: 10250966 | B37: Jumana Ashraf | C37: CSR | D37: Production | E37: {=_xlfn.XLOOKUP(A37,'Schedule Wk 47'!A:A,'Schedule Wk 47'!E:E,"")} -> FT | F37: {=_xlfn.XLOOKUP(A37,'Schedule Wk 47'!A:A,'Schedule Wk 47'!F:F,"")} -> 3 | G37: 0.375 | H37: 0.75 | I37: 0.375 | J37: 0.75 | K37: 0.375 | L37: 0.75 | M37: 0.375 | N37: 0.75 | O37: 0.375 | P37: 0.75 | Q37: OFF | R37: OFF | S37: OFF | T37: OFF | U37: =IFERROR(__xludf.DUMMYFUNCTION("TO_PURE_NUMBER(SUM(FILTER(G37:T37, ISEVEN(COLUMN(G37:T37))))-SUM(FILTER(G37:T37, ISODD(COLUMN(G37:T37)))))*24"),45) -> 45 | V37: {=_xlfn.XLOOKUP(A37,'WK 47'!A:A,'WK 47'!V:V,"")} -> 45 | W37: {=_xlfn.XLOOKUP(A37,'WK 47'!A:A,'WK 47'!AA:AA,"")} -> early | X37: =V37-U37 -> 0 | Y37: 0.41666667
A38: 10317943 | B38: Hla Badr | C38: CSR | D38: Production | E38: {=_xlfn.XLOOKUP(A38,'Schedule Wk 47'!A:A,'Schedule Wk 47'!E:E,"")} -> FT | F38: {=_xlfn.XLOOKUP(A38,'Schedule Wk 47'!A:A,'Schedule Wk 47'!F:F,"")} -> 2 | G38: 0.45833333 | H38: 0.875 | I38: 0.45833333 | J38: 0.875 | K38: 0.45833333 | L38: 0.875 | M38: 0.45833333 | N38: 0.875 | O38: OFF | P38: OFF | Q38: OFF | R38: OFF | S38: 0.45833333 | T38: 0.66666667 | U38: =IFERROR(__xludf.DUMMYFUNCTION("TO_PURE_NUMBER(SUM(FILTER(G38:T38, ISEVEN(COLUMN(G38:T38))))-SUM(FILTER(G38:T38, ISODD(COLUMN(G38:T38)))))*24"),45) -> 45 | V38: {=_xlfn.XLOOKUP(A38,'WK 47'!A:A,'WK 47'!V:V,"")} -> 45 | W38: {=_xlfn.XLOOKUP(A38,'WK 47'!A:A,'WK 47'!AA:AA,"")} -> early | X38: =V38-U38 -> 0 | Y38: 0.41666667
A39: 10316530 | B39: Hassan Hussain | C39: CSR | D39: Production | E39: {=_xlfn.XLOOKUP(A39,'Schedule Wk 47'!A:A,'Schedule Wk 47'!E:E,"")} -> FT | F39: {=_xlfn.XLOOKUP(A39,'Schedule Wk 47'!A:A,'Schedule Wk 47'!F:F,"")} -> 1 | G39: OFF | H39: OFF | I39: 0.45833333 | J39: 0.875 | K39: 0.45833333 | L39: 0.875 | M39: 0.45833333 | N39: 0.875 | O39: 0.45833333 | P39: 0.875 | Q39: 0.45833333 | R39: 0.66666667 | S39: OFF | T39: OFF | U39: =IFERROR(__xludf.DUMMYFUNCTION("TO_PURE_NUMBER(SUM(FILTER(G39:T39, ISEVEN(COLUMN(G39:T39))))-SUM(FILTER(G39:T39, ISODD(COLUMN(G39:T39)))))*24"),45) -> 45 | V39: {=_xlfn.XLOOKUP(A39,'WK 47'!A:A,'WK 47'!V:V,"")} -> 45 | W39: {=_xlfn.XLOOKUP(A39,'WK 47'!A:A,'WK 47'!AA:AA,"")} -> late | X39: =V39-U39 -> 0 | Y39: 0.41666667
A40: 10316681 | B40: Habiba Morsy | C40: Esc Mgr | D40: Production | E40: {=_xlfn.XLOOKUP(A40,'Schedule Wk 47'!A:A,'Schedule Wk 47'!E:E,"")} -> FT | F40: {=_xlfn.XLOOKUP(A40,'Schedule Wk 47'!A:A,'Schedule Wk 47'!F:F,"")} -> 1 | G40: 0.375 | H40: 0.75 | I40: 0.375 | J40: 0.75 | K40: 0.375 | L40: 0.75 | M40: 0.375 | N40: 0.75 | O40: 0.375 | P40: 0.75 | Q40: OFF | R40: OFF | S40: OFF | T40: OFF | U40: =IFERROR(__xludf.DUMMYFUNCTION("TO_PURE_NUMBER(SUM(FILTER(G40:T40, ISEVEN(COLUMN(G40:T40))))-SUM(FILTER(G40:T40, ISODD(COLUMN(G40:T40)))))*24"),45) -> 45 | V40: {=_xlfn.XLOOKUP(A40,'WK 47'!A:A,'WK 47'!V:V,"")} -> 45 | W40: {=_xlfn.XLOOKUP(A40,'WK 47'!A:A,'WK 47'!AA:AA,"")} -> early | X40: =V40-U40 -> 0 | Y40: {=_xlfn.XLOOKUP(A40,'WK 45'!A:A,'WK 45'!X:X,"")} -> 0.375
...

Sheet WK2 UPDATED
A1: CIM | B1: Agent Name | C1: Position | D1: Stage | E1: FT/PT | F1: Wave | G1: 45663 | I1: 45664 | K1: 45665 | M1: 45666 | O1: 45667 | Q1: 45668 | S1: 45669
G2: Monday | I2: Tuesday | K2: Wednesday | M2: Thursday | O2: Friday | Q2: Saturday | S2: Sunday
G3: From | H3: To | I3: From | J3: To | K3: From | L3: To | M3: From | N3: To | O3: From | P3: To | Q3: From | R3: To | S3: From | T3: To
A4: 10320410 | B4: Abdelrahman Etman | C4: CSR | D4: Production | E4: FT | F4: 3 | G4: 0.375 | H4: 0.75 | I4: 0.375 | J4: 0.75 | K4: 0.375 | L4: 0.75 | M4: 0.375 | N4: 0.75 | O4: 0.375 | P4: 0.75 | Q4: OFF | R4: OFF | S4: OFF | T4: OFF
A5: 10320415 | B5: Abdelrahman Ibrahim | C5: CSR | D5: Production | E5: FT | F5: 3 | G5: 0.45833333 | H5: 0.875 | I5: 0.45833333 | J5: 0.875 | K5: 0.45833333 | L5: 0.875 | M5: 0.45833333 | N5: 0.875 | O5: OFF | P5: OFF | Q5: OFF | R5: OFF | S5: 0.45833333 | T5: 0.66666667
A6: 10317522 | B6: Ahmed Hisham | C6: CSR | D6: Production | E6: FT | F6: 2 | G6: AN | H6: AN | I6: BH | J6: BH | K6: 0.45833333 | L6: 0.875 | M6: 0.45833333 | N6: 0.875 | O6: OFF | P6: OFF | Q6: OFF | R6: OFF | S6: 0.45833333 | T6: 0.66666667
A7: 10316549 | B7: Ahmed Mamdouh | C7: CSR | D7: B2B | E7: FT | F7: 1 | G7: AN | H7: AN | I7: 0.375 | J7: 0.75 | K7: 0.375 | L7: 0.75 | M7: 0.375 | N7: 0.75 | O7: 0.375 | P7: 0.75 | Q7: OFF | R7: OFF | S7: OFF | T7: OFF
A8: 10320413 | B8: Alaa Abdulshafi | C8: CSR | D8: Production | E8: FT | F8: 3 | G8: 0.45833333 | H8: 0.875 | I8: 0.45833333 | J8: 0.875 | K8: 0.45833333 | L8: 0.875 | M8: 0.45833333 | N8: 0.875 | O8: OFF | P8: OFF | Q8: OFF | R8: OFF | S8: 0.45833333 | T8: 0.66666667
A9: 10320408 | B9: Alaa Ali | C9: CSR | D9: Production | E9: FT | F9: 3 | G9: 0.375 | H9: 0.75 | I9: 0.375 | J9: 0.75 | K9: 0.375 | L9: 0.75 | M9: 0.375 | N9: 0.75 | O9: OFF | P9: OFF | Q9: OFF | R9: OFF | S9: 0.45833333 | T9: 0.66666667
A10: 10317147 | B10: Asalla Metwally | C10: CSR | D10: Production | E10: FT | F10: 1 | G10: OFF | H10: OFF | I10: 0.45833333 | J10: 0.875 | K10: 0.45833333 | L10: 0.875 | M10: 0.45833333 | N10: 0.875 | O10: 0.45833333 | P10: 0.875 | Q10: 0.45833333 | R10: 0.66666667 | S10: OFF | T10: OFF
A11: 10272259 | B11: Aya Hassan | C11: CSR | D11: Production | E11: FT | F11: 2 | G11: 0.33333333 | H11: 0.70833333 | I11: OFF | J11: OFF | K11: OFF | L11: OFF | M11: AN | N11: AN | O11: AN | P11: AN | Q11: AN | R11: AN | S11: 0.41666667 | T11: 0.625
A12: 10320412 | B12: Bassant Amin | C12: CSR | D12: Production | E12: FT | F12: 3 | G12: 0.5 | H12: 0.875 | I12: 0.5 | J12: 0.875 | K12: 0.5 | L12: 0.875 | M12: 0.5 | N12: 0.875 | O12: 0.5 | P12: 0.875 | Q12: OFF | R12: OFF | S12: OFF | T12: OFF
A13: 10320418 | B13: Bassant Eissa | C13: CSR | D13: Production | E13: FT | F13: 3 | G13: 0.375 | H13: 0.75 | I13: 0.375 | J13: 0.75 | K13: 0.375 | L13: 0.75 | M13: 0.375 | N13: 0.75 | O13: OFF | P13: OFF | Q13: OFF | R13: OFF | S13: 0.45833333 | T13: 0.66666667
A14: 10316618 | B14: Caren Lawendi | C14: CSR | D14: B2B | E14: FT | F14: 1 | G14: AN | H14: AN | I14: BH | J14: BH | K14: 0.5 | L14: 0.875 | M14: 0.5 | N14: 0.875 | O14: 0.5 | P14: 0.875 | Q14: OFF | R14: OFF | S14: OFF | T14: OFF
A15: 10250963 | B15: Dina Hanafy | C15: CSR | D15: Production | E15: FT | F15: 1 | G15: 0.5 | H15: 0.875 | I15: 0.5 | J15: 0.875 | K15: 0.5 | L15: 0.875 | M15: 0.5 | N15: 0.875 | O15: 0.5 | P15: 0.875 | Q15: OFF | R15: OFF | S15: OFF | T15: OFF
A16: 10295555 | B16: Duaa Elshareeff | C16: CSR | D16: Production | E16: PT | F16: 2 | G16: 0.66666667 | H16: 0.875 | I16: 0.66666667 | J16: 0.875 | K16: OFF | L16: OFF | M16: OFF | N16: OFF | O16: 0.66666667 | P16: 0.875 | Q16: 0.45833333 | R16: 0.66666667 | S16: 0.45833333 | T16: 0.66666667
A17: 10317520 | B17: Farida Gadalkarim | C17: CSR | D17: Production | E17: FT | F17: 2 | G17: OFF | H17: OFF | I17: 0.33333333 | J17: 0.75 | K17: 0.33333333 | L17: 0.75 | M17: 0.33333333 | N17: 0.75 | O17: 0.33333333 | P17: 0.75 | Q17: 0.41666667 | R17: 0.625 | S17: OFF | T17: OFF
A18: 10320414 | B18: Fatimaalzahra Hafez | C18: CSR | D18: Production | E18: FT | F18: 3 | G18: OFF | H18: OFF | I18: 0.375 | J18: 0.79166667 | K18: 0.375 | L18: 0.79166667 | M18: 0.375 | N18: 0.79166667 | O18: 0.375 | P18: 0.79166667 | Q18: 0.45833333 | R18: 0.66666667 | S18: OFF | T18: OFF
A19: 10316681 | B19: Habiba Morsy | C19: Esc Mgr | D19: Production | E19: FT | F19: 1 | G19: 0.375 | H19: 0.75 | I19: 0.375 | J19: 0.75 | K19: 0.375 | L19: 0.75 | M19: 0.375 | N19: 0.75 | O19: 0.375 | P19: 0.75 | Q19: OFF | R19: OFF | S19: OFF | T19: OFF
A20: 10316650 | B20: Hana Afifi | C20: CSR | D20: Production | E20: FT | F20: 2 | G20: 0.375 | H20: 0.79166667 | I20: 0.375 | J20: 0.79166667 | K20: 0.375 | L20: 0.79166667 | M20: 0.375 | N20: 0.79166667 | O20: OFF | P20: OFF | Q20: OFF | R20: OFF | S20: 0.45833333 | T20: 0.66666667
A21: 10320416 | B21: Hana Jankiz | C21: CSR | D21: Production | E21: FT | F21: 3 | G21: 0.5 | H21: 0.875 | I21: 0.5 | J21: 0.875 | K21: 0.5 | L21: 0.875 | M21: 0.5 | N21: 0.875 | O21: 0.5 | P21: 0.875 | Q21: OFF | R21: OFF | S21: OFF | T21: OFF
A22: 10316530 | B22: Hassan Hussain | C22: CSR | D22: Production | E22: FT | F22: 1 | G22: AN | H22: AN | I22: BH | J22: BH | K22: AN | L22: AN | M22: 0.5 | N22: 0.875 | O22: 0.5 | P22: 0.875 | Q22: OFF | R22: OFF | S22: OFF | T22: OFF
A23: 10316680 | B23: Hesham Hussien | C23: CSR | D23: Production | E23: FT | F23: 1 | G23: 0.5 | H23: 0.875 | I23: 0.5 | J23: 0.875 | K23: 0.5 | L23: 0.875 | M23: 0.5 | N23: 0.875 | O23: 0.5 | P23: 0.875 | Q23: OFF | R23: OFF | S23: OFF | T23: OFF
A24: 10317943 | B24: Hla Badr | C24: CSR | D24: Production | E24: FT | F24: 2 | G24: 0.45833333 | H24: 0.875 | I24: 0.45833333 | J24: 0.875 | K24: 0.45833333 | L24: 0.875 | M24: 0.45833333 | N24: 0.875 | O24: OFF | P24: OFF | Q24: OFF | R24: OFF | S24: 0.45833333 | T24: 0.66666667
A25: 10250966 | B25: Jumana Ashraf | C25: CSR | D25: Production | E25: FT | F25: 3 | G25: 0.45833333 | H25: 0.875 | I25: 0.45833333 | J25: 0.875 | K25: 0.45833333 | L25: 0.875 | M25: 0.45833333 | N25: 0.875 | O25: OFF | P25: OFF | Q25: OFF | R25: OFF | S25: 0.45833333 | T25: 0.66666667
A26: 10316543 | B26: Khaled Zaafarany | C26: CSR | D26: Production | E26: FT | F26: 1 | G26: 0.45833333 | H26: 0.875 | I26: 0.45833333 | J26: 0.875 | K26: 0.45833333 | L26: 0.875 | M26: 0.45833333 | N26: 0.875 | O26: OFF | P26: OFF | Q26: OFF | R26: OFF | S26: 0.45833333 | T26: 0.66666667
A27: 10317521 | B27: Mariam Gadalkarim | C27: CSR | D27: Production | E27: FT | F27: 2 | G27: OFF | H27: OFF | I27: 0.33333333 | J27: 0.75 | K27: 0.33333333 | L27: 0.75 | M27: 0.33333333 | N27: 0.75 | O27: 0.33333333 | P27: 0.75 | Q27: 0.41666667 | R27: 0.625 | S27: OFF | T27: OFF
A28: 10317517 | B28: Mariam Hanna | C28: CSR | D28: Production | E28: FT | F28: 2 | G28: 0.375 | H28: 0.75 | I28: BH | J28: BH | K28: AN | L28: AN | M28: 0.375 | N28: 0.75 | O28: 0.375 | P28: 0.75 | Q28: OFF | R28: OFF | S28: OFF | T28: OFF
A29: 10252106 | B29: Marinass Elhusseni | C29: CSR | D29: Production | E29: FT | F29: 2 | G29: 0.375 | H29: 0.75 | I29: OFF | J29: OFF | K29: OFF | L29: OFF | M29: 0.375 | N29: 0.75 | O29: AN | P29: AN | Q29: AN | R29: AN | S29: 0.45833333 | T29: 0.66666667
A30: 10320407 | B30: Marleen Francis | C30: CSR | D30: Production | E30: FT | F30: 3 | G30: OFF | H30: OFF | I30: BH | J30: BH | K30: 0.375 | L30: 0.79166667 | M30: 0.375 | N30: 0.79166667 | O30: 0.375 | P30: 0.79166667 | Q30: 0.45833333 | R30: 0.66666667 | S30: OFF | T30: OFF
A31: 10320417 | B31: Marwa Nofal | C31: CSR | D31: Production | E31: FT | F31: 3 | G31: 0.375 | H31: 0.79166667 | I31: BH | J31: BH | K31: 0.375 | L31: 0.79166667 | M31: 0.375 | N31: 0.79166667 | O31: OFF | P31: OFF | Q31: OFF | R31: OFF | S31: 0.45833333 | T31: 0.66666667
A32: 10317154 | B32: Mazen Elramlawy | C32: CSR | D32: Production | E32: FT | F32: 3 | G32: 0.33333333 | H32: 0.75 | I32: 0.33333333 | J32: 0.75 | K32: 0.33333333 | L32: 0.75 | M32: 0.33333333 | N32: 0.75 | O32: OFF | P32: OFF | Q32: OFF | R32: OFF | S32: 0.41666667 | T32: 0.625
A33: 10320436 | B33: Mazen Shoukry | C33: CSR | D33: Production | E33: FT | F33: 3 | G33: 0.375 | H33: 0.79166667 | I33: 0.375 | J33: 0.79166667 | K33: 0.375 | L33: 0.79166667 | M33: 0.375 | N33: 0.79166667 | O33: OFF | P33: OFF | Q33: OFF | R33: OFF | S33: 0.45833333 | T33: 0.66666667
A34: 10316538 | B34: Mohamed Abdelrahman | C34: CSR | D34: Production | E34: FT | F34: 1 | G34: 0.5 | H34: 0.875 | I34: 0.5 | J34: 0.875 | K34: OFF | L34: OFF | M34: OFF | N34: OFF | O34: 0.5 | P34: 0.875 | Q34: 0.45833333 | R34: 0.66666667 | S34: 0.45833333 | T34: 0.66666667
A35: 10293607 | B35: Mohamed Hassan | C35: CSR | D35: Production | E35: FT | F35: 3 | G35: 0.45833333 | H35: 0.875 | I35: 0.45833333 | J35: 0.875 | K35: 0.45833333 | L35: 0.875 | M35: 0.45833333 | N35: 0.875 | O35: OFF | P35: OFF | Q35: OFF | R35: OFF | S35: 0.45833333 | T35: 0.66666667
A36: 10316545 | B36: Nada Mosbah | C36: CSR | D36: Production | E36: FT | F36: 1 | G36: 0.375 | H36: 0.75 | I36: 0.375 | J36: 0.75 | K36: 0.375 | L36: 0.75 | M36: 0.375 | N36: 0.75 | O36: 0.375 | P36: 0.75 | Q36: OFF | R36: OFF | S36: OFF | T36: OFF
